<?xml version="1.0" ?>
<robot name="plane">
  <link name="chassis">
  <contact>
      <lateral_friction value="1"/>
  </contact>
    <inertial>
      <origin rpy="0 0 0" xyz="0 0.03 0.043794"/>
       <mass value="13.715"/>
       <inertia ixx="0" ixy="0" ixz="0" iyy="0" iyz="0" izz="0"/>
    </inertial>
    <visual>
      <origin rpy="0 0 0" xyz="0 0 0.043794"/>
      <geometry>
      	
				<mesh filename="chassis.stl" scale="1 1 1"/>
      </geometry>
       <material name="yellow">
        <color rgba="0.95 0.75 0.05 1"/>
      </material>
    </visual>
    <collision>
      <origin rpy="-1.57 0 0" xyz="0 0 0.043794"/>
      <geometry>
      	
				<mesh filename="chassis_vhacd_mod.obj" scale="1 1 1"/>
      </geometry>
    </collision>
  </link>
  
 
	
	 <link name="FR_hip_motor">
  <contact>
      <lateral_friction value="1"/>
  </contact>
    <inertial>
       <origin rpy="0 0 0" xyz="0.02 0 0"/>
       <mass value="1.095"/>
       <inertia ixx="0" ixy="0" ixz="0" iyy="0" iyz="0" izz="0"/>
    </inertial>
	
	  <visual>
      <origin rpy="0 0 0" xyz="0 0 0"/>
      <geometry>
				<mesh filename="hip_motor_mirror.stl" scale="1 1 1"/>
      </geometry>
       <material name="black">
        <color rgba="0 0 0 1"/>
      </material>
    </visual>
    
    <collision>
      <origin rpy="0 0 0" xyz="0 0 0"/>
      <geometry>
				<mesh filename="hip_motor_mirror.stl" scale="1 1 1"/>
      </geometry>
    </collision>
    </link>
    
    <joint name="FR_hip_motor_2_chassis_joint" type="continuous">
		<axis xyz="0 0 -1"/>
		<parent link="chassis"/>
		<child link="FR_hip_motor"/>
		<origin rpy="0 0 0" xyz="-0.0817145 0 0.242889"/>
		<limit effort="100" velocity="100"/>
		<joint_properties damping=".0" friction=".0"/>
	</joint>
	
     <link name="FR_upper_leg">
  <contact>
      <lateral_friction value="1"/>
  </contact>
    <inertial>
     <origin rpy="0 0 0" xyz="0 -0.04 -0.04"/>
       <mass value="1.527"/>
       <inertia ixx="0" ixy="0" ixz="0" iyy="0" iyz="0" izz="0"/>
    </inertial>
       <visual>
      <origin rpy="0 0 0" xyz="0 0 0"/>
      <geometry>
				<mesh filename="upper_leg_mirror.stl" scale="1 1 1"/>
      </geometry>
       <material name="yellow">
        <color rgba="0.95 0.75 0.05 1"/>
      </material>
    </visual>
    
    <collision>
      <origin rpy="0 0 0" xyz="0 0 0"/>
      <geometry>
				<mesh filename="upper_leg_right_vhacd.obj" scale="1 1 1"/>
      </geometry>
    </collision>
    
    </link>
    
    <joint name="FR_upper_leg_2_hip_motor_joint" type="continuous">
		<axis xyz="1 0 0"/>
		<parent link="FR_hip_motor"/>
		<child link="FR_upper_leg"/>
		<origin rpy="0 0 0" xyz="-0.053565 0 0"/>
		<limit effort="100" velocity="100"/>
		<joint_properties damping=".0" friction=".0"/>
	</joint>
	
     <link name="FR_lower_leg">
  <contact>
      <lateral_friction value="1"/>
  </contact>
    <inertial>
      <origin rpy="0 0 0" xyz="0 -0.16 -0.02"/>
       <mass value="0.241"/>
       <inertia ixx="0" ixy="0" ixz="0" iyy="0" iyz="0" izz="0"/>
    </inertial>
       <visual>
      <origin rpy="0 1.57079 0" xyz="0 0.0 0"/>
      <geometry>
				<mesh filename="lower_leg_3.stl" scale="1 1 1"/>
      </geometry>
       <material name="black">
        <color rgba="0 0 0 1"/>
      </material>
    </visual>
    
    <collision>
      <origin rpy="0 1.57079 0" xyz="0 0.0 0"/>
      <geometry>
				<mesh filename="lower_leg_3.stl" scale="1 1 1"/>
      </geometry>
    </collision>
    
    </link>
    
    <joint name="FR_lower_leg_2_upper_leg_joint" type="continuous">
		<axis xyz="1 0 0"/>
		<parent link="FR_upper_leg"/>
		<child link="FR_lower_leg"/>
														
		<origin rpy="0 0 0" xyz="0.02069  -0.20833  -0.1422"/>
		<limit effort="100" velocity="100"/>
		<joint_properties damping=".0" friction=".0"/>
	</joint>
	
	
	 <link name="FL_hip_motor">
  <contact>
      <lateral_friction value="1"/>
  </contact>
    <inertial>
     <origin rpy="0 0 0" xyz="-.02 0 0"/>
       <mass value="1.095"/>
       <inertia ixx="0" ixy="0" ixz="0" iyy="0" iyz="0" izz="0"/>
    </inertial>
    <visual>
      <origin rpy="0 0 0" xyz="0 0 0"/>
      <geometry>
				<mesh filename="hip_motor.stl" scale="1 1 1"/>
      </geometry>
       <material name="black">
        <color rgba="0 0 0 1"/>
      </material>
      
    </visual>
    
    <collision>
      <origin rpy="0 0 0" xyz="0 0 0"/>
      <geometry>
				<mesh filename="hip_motor.stl" scale="1 1 1"/>
      </geometry>
    </collision>
    
      </link>
  
   <joint name="FL_hip_motor_2_chassis_joint" type="continuous">
		<axis xyz="0 0 1"/>
		<parent link="chassis"/>
		<child link="FL_hip_motor"/>
		<origin rpy="0 0 0" xyz="0.0817145 0 0.242889"/>
		<limit effort="100" velocity="100"/>
		<joint_properties damping=".0" friction=".0"/>
	</joint>
	
  <link name="FL_upper_leg">
  <contact>
      <lateral_friction value="1"/>
  </contact>
    <inertial>
       <origin rpy="0 0 0" xyz="0 -0.04 -0.04"/>
       <mass value="1.527"/>
       <inertia ixx="0" ixy="0" ixz="0" iyy="0" iyz="0" izz="0"/>
    </inertial>
     <visual>
      <origin rpy="0 0 0" xyz="0 0 0"/>
      <geometry>
      	
				<mesh filename="upper_leg.stl" scale="1 1 1"/>
      </geometry>
       <material name="yellow">
        <color rgba="0.95 0.75 0.05 1"/>
      </material>
    </visual>
    
     <collision>
      <origin rpy="0 0 0" xyz="0 0 0"/>
      <geometry>
				<mesh filename="upper_leg_left_vhacd.obj" scale="1 1 1"/>
      </geometry>
    </collision>
    
    </link>
  
  
  <joint name="FL_upper_leg_2_hip_motor_joint" type="continuous">
		<axis xyz="1 0 0"/>
		<parent link="FL_hip_motor"/>
		<child link="FL_upper_leg"/>
		<origin rpy="0 0 0" xyz="0.055855  0 0"/>
		<limit effort="100" velocity="100"/>
		<joint_properties damping=".0" friction=".0"/>
	</joint>
	 
  
  <link name="FL_lower_leg">
  <contact>
      <lateral_friction value="1"/>
  </contact>
    <inertial>
      <origin rpy="0 0 0" xyz="0 -0.16 -0.02"/>
       <mass value="0.241"/>
       <inertia ixx="0" ixy="0" ixz="0" iyy="0" iyz="0" izz="0"/>
    </inertial>
   <visual>
      <origin rpy="0 1.57079 0" xyz="0 0 0"/>
      <geometry>
				<mesh filename="lower_leg_3.stl" scale="1 1 1"/>
      </geometry>
       <material name="black">
        <color rgba="0 0 0 1"/>
      </material>
    </visual>
    
     <collision>
      <origin rpy="0 1.57079 0" xyz="0 0 0"/>
      <geometry>
				<mesh filename="lower_leg_3.stl" scale="1 1 1"/>
      </geometry>
    </collision>
    
    </link>
    
  <joint name="FL_lower_leg_2_upper_leg_joint" type="continuous">
		<axis xyz="1 0 0"/>
		<parent link="FL_upper_leg"/>
		<child link="FL_lower_leg"/>
		<origin rpy="0 0 0" xyz="-0.02069  -0.20833  -0.1422"/>
		<limit effort="100" velocity="100"/>
		<joint_properties damping=".0" friction=".0"/>
	</joint>
	
	
	
	
	
	
	 <link name="RR_hip_motor">
  <contact>
      <lateral_friction value="1"/>
  </contact>
    <inertial>
      <origin rpy="0 0 0" xyz="0.02 0 0"/>
       <mass value="1.095"/>
       <inertia ixx="0" ixy="0" ixz="0" iyy="0" iyz="0" izz="0"/>
    </inertial>
	
	  <visual>
      <origin rpy="0 0 0" xyz="0 0 0"/>
      <geometry>
				<mesh filename="hip_motor_mirror.stl" scale="1 1 1"/>
      </geometry>
       <material name="black">
        <color rgba="0 0 0 1"/>
      </material>
    </visual>
    
     <collision>
      <origin rpy="0 0 0" xyz="0 0 0"/>
      <geometry>
				<mesh filename="hip_motor_mirror.stl" scale="1 1 1"/>
      </geometry>
    </collision>
    
    </link>
    
    <joint name="RR_hip_motor_2_chassis_joint" type="continuous">
		<axis xyz="0 0 -1"/>
		<parent link="chassis"/>
		<child link="RR_hip_motor"/>
		<origin rpy="0 0 0" xyz="-0.0817145 0 -0.194401"/>
		<limit effort="100" velocity="100"/>
		<joint_properties damping=".0" friction=".0"/>
	</joint>
	
     <link name="RR_upper_leg">
  <contact>
      <lateral_friction value="1"/>
  </contact>
    <inertial>
     <origin rpy="0 0 0" xyz="0 -0.04 -0.04"/>
       <mass value="1.527"/>
       <inertia ixx="0" ixy="0" ixz="0" iyy="0" iyz="0" izz="0"/>
    </inertial>
       <visual>
      <origin rpy="0 0 0" xyz="0 0 0"/>
      <geometry>
				<mesh filename="upper_leg_mirror.stl" scale="1 1 1"/>
      </geometry>
       <material name="yellow">
        <color rgba="0.95 0.75 0.05 1"/>
      </material>
    </visual>
    
    <collision>
      <origin rpy="0 0 0" xyz="0 0 0"/>
      <geometry>
				<mesh filename="upper_leg_right_vhacd.obj" scale="1 1 1"/>
      </geometry>
    </collision>
    
    </link>
    
    <joint name="RR_upper_leg_2_hip_motor_joint" type="continuous">
		<axis xyz="1 0 0"/>
		<parent link="RR_hip_motor"/>
		<child link="RR_upper_leg"/>
		<origin rpy="0 0 0" xyz="-0.053565 0 0"/>
		<limit effort="100" velocity="100"/>
		<joint_properties damping=".0" friction=".0"/>
	</joint>
	
     <link name="RR_lower_leg">
  <contact>
      <lateral_friction value="1"/>
  </contact>
    <inertial>
      <origin rpy="0 0 0" xyz="0 -0.16 -0.02"/>
       <mass value="0.241"/>
       <inertia ixx="0" ixy="0" ixz="0" iyy="0" iyz="0" izz="0"/>
    </inertial>
       <visual>
      <origin rpy="0 1.57079 0" xyz="0 0 0"/>
      <geometry>
				<mesh filename="lower_leg_3.stl" scale="1 1 1"/>
      </geometry>
       <material name="black">
        <color rgba="0 0 0 1"/>
      </material>
    </visual>
    
     <collision>
      <origin rpy="0 1.57079 0" xyz="0 0 0"/>
      <geometry>
				<mesh filename="lower_leg_3.stl" scale="1 1 1"/>
      </geometry>
    </collision>
    
    </link>
    
    <joint name="RR_lower_leg_2_upper_leg_joint" type="continuous">
		<axis xyz="1 0 0"/>
		<parent link="RR_upper_leg"/>
		<child link="RR_lower_leg"/>
		<origin rpy="0 0 0" xyz="0.02069  -0.20833  -0.1422"/>
		<limit effort="100" velocity="100"/>
		<joint_properties damping=".0" friction=".0"/>
	</joint>
	
	
	 <link name="RL_hip_motor">
  <contact>
      <lateral_friction value="1"/>
  </contact>
    <inertial>
      <origin rpy="0 0 0" xyz="-.02 0 0"/>
       <mass value="1.095"/>
       <inertia ixx="0" ixy="0" ixz="0" iyy="0" iyz="0" izz="0"/>
    </inertial>
    <visual>
      <origin rpy="0 0 0" xyz="0 0 0"/>
      <geometry>
				<mesh filename="hip_motor.stl" scale="1 1 1"/>
      </geometry>
       <material name="black">
        <color rgba="0 0 0 1"/>
      </material>
    </visual>
    
    <collision>
      <origin rpy="0 0 0" xyz="0 0 0"/>
      <geometry>
				<mesh filename="hip_motor.stl" scale="1 1 1"/>
      </geometry>
    </collision>
    
      </link>
  
   <joint name="RL_hip_motor_2_chassis_joint" type="continuous">
		<axis xyz="0 0 1"/>
		<parent link="chassis"/>
		<child link="RL_hip_motor"/>
												
		<origin rpy="0 0 0" xyz="0.0817145 0 -0.194401"/>
		<limit effort="100" velocity="100"/>
		<joint_properties damping=".0" friction=".0"/>
	</joint>
	
  <link name="RL_upper_leg">
  <contact>
      <lateral_friction value="1"/>
  </contact>
    <inertial>
      <origin rpy="0 0 0" xyz="0 -0.04 -0.04"/>
       <mass value="1.527"/>
       <inertia ixx="0" ixy="0" ixz="0" iyy="0" iyz="0" izz="0"/>
    </inertial>
     <visual>
      <origin rpy="0 0 0" xyz="0 0 0"/>
      <geometry>
				<mesh filename="upper_leg.stl" scale="1 1 1"/>
      </geometry>
       <material name="yellow">
        <color rgba="0.95 0.75 0.05 1"/>
      </material>
    </visual>
    
    <collision>
      <origin rpy="0 0 0" xyz="0 0 0"/>
      <geometry>
				<mesh filename="upper_leg_left_vhacd.obj" scale="1 1 1"/>
      </geometry>
    </collision>
    
    </link>
  
  
  <joint name="RL_upper_leg_2_hip_motor_joint" type="continuous">
		<axis xyz="1 0 0"/>
		<parent link="RL_hip_motor"/>
		<child link="RL_upper_leg"/>
		<origin rpy="0 0 0" xyz="0.055855  0 0"/>
		<limit effort="100" velocity="100"/>
		<joint_properties damping=".0" friction=".0"/>
	</joint>
	 
  
  <link name="RL_lower_leg">
  <contact>
      <lateral_friction value="1"/>
  </contact>
    <inertial>
      <origin rpy="0 0 0" xyz="0 -0.16 -0.02"/>
       <mass value="0.241"/>
       <inertia ixx="0" ixy="0" ixz="0" iyy="0" iyz="0" izz="0"/>
    </inertial>
   <visual>
      <origin rpy="0 1.57079 0" xyz="0 0 0"/>
      <geometry>
				<mesh filename="lower_leg_3.stl" scale="1 1 1"/>
      </geometry>
       <material name="black">
        <color rgba="0 0 0 1"/>
      </material>
    </visual>
    
    <collision>
      <origin rpy="0 1.57079 0" xyz="0 0 0"/>
      <geometry>
				<mesh filename="lower_leg_3.stl" scale="1 1 1"/>
      </geometry>
    </collision>
    
    </link>
    
  <joint name="RL_lower_leg_2_upper_leg_joint" type="continuous">
		<axis xyz="1 0 0"/>
		<parent link="RL_upper_leg"/>
		<child link="RL_lower_leg"/>
		<origin rpy="0 0 0" xyz="-0.02069  -0.20833  -0.1422"/>
		<limit effort="100" velocity="100"/>
		<joint_properties damping=".0" friction=".0"/>
	</joint>
	
	<link name="gripper_base">
      <contact>
          <lateral_friction value="1"/>
      </contact>
        <inertial>
          <origin rpy="0 0 0" xyz="0 0 0"/>
           <mass value="0.241"/>
           <inertia ixx="0" ixy="0" ixz="0" iyy="0" iyz="0" izz="0"/>
        </inertial>
       <visual>
          <origin rpy="0 0 0" xyz="-0.06 0 -0.06"/>
          <geometry>
                    <mesh filename="gripper_base.stl" scale="1 1 1"/>
          </geometry>
           <material name="black">
            <color rgba="0 0 0 1"/>
          </material>
        </visual>
        
        <collision  >
          <origin rpy="0 0 0" xyz="0 0 0"/>
          <geometry>
                    <mesh filename="gripper_base.stl" scale="1 1 1"/>
          </geometry>
        </collision>
    </link>
    
	<joint name="chassis_gripper_base" type="continuous">
		<axis xyz="0 1 0"/>
		<parent link="chassis"/>
		<child link="gripper_base"/>
		<origin rpy="0 0 0" xyz="0 0.11 0.12"/>
		<limit effort="100" velocity="100"/>
		<joint_properties damping=".0" friction=".0"/>
	</joint>
    
    <link name="gripper_lower_arm">
      <contact>
          <lateral_friction value="1"/>
      </contact>
        <inertial>
          <origin rpy="0 1.57 0" xyz="0 -0.03 0"/>
           <mass value="0.241"/>
           <inertia ixx="0" ixy="0" ixz="0" iyy="0" iyz="0" izz="0"/>
        </inertial>
       <visual>
          <origin rpy="0 1.57 0" xyz="0 -0.03 0"/>
          <geometry>
                    <mesh filename="gripper_lower_arm.stl" scale="1 1 1"/>
          </geometry>
           <material name="yellow">
          </material>
        </visual>
        
        <collision  >
          <origin rpy="0 1.57 0" xyz="0 -0.03 0"/>
          <geometry>
                    <mesh filename="gripper_lower_arm.stl" scale="1 1 1"/>
          </geometry>
        </collision>
    </link>
    
	<joint name="gripper_base_gripper_lower_arm" type="continuous">
		<axis xyz="1 0 0"/>
		<parent link="gripper_base"/>
		<child link="gripper_lower_arm"/>
		<origin rpy="0 0 0" xyz="-0.03 0.08 0"/>
		<limit effort="100" velocity="100"/>
		<joint_properties damping=".0" friction=".0"/>
	</joint>
    
   <link name="gripper_upper_arm">
      <contact>
          <lateral_friction value="1"/>
      </contact>
        <inertial>
          <origin rpy="0 1.57 0" xyz="0 0 0.36"/>
           <mass value="0.241"/>
           <inertia ixx="0" ixy="0" ixz="0" iyy="0" iyz="0" izz="0"/>
        </inertial>
       <visual>
          <origin rpy="0 1.57 0" xyz="0 0 0.36"/>
          <geometry>
                    <mesh filename="gripper_upper_arm.stl" scale="1 1 1"/>
          </geometry>
           <material name="black">
          </material>
        </visual>
        
        <collision  >
          <origin rpy="0 1.57 0" xyz="0 0 0.36"/>
          <geometry>
                    <mesh filename="gripper_upper_arm.stl" scale="1 1 1"/>
          </geometry>
        </collision>
    </link>
    
	<joint name="gripper_lower_arm_gripper_upper_arm" type="continuous">
		<axis xyz="1 0 0"/>
		<parent link="gripper_lower_arm"/>
		<child link="gripper_upper_arm"/>
		<origin rpy="0 0 0" xyz="0 0 -0.33"/>
		<limit effort="100" velocity="100"/>
		<joint_properties damping=".0" friction=".0"/>
	</joint>
    
     <link name="gripper1">
      <contact>
          <lateral_friction value="1"/>
      </contact>
        <inertial>
          <origin rpy="0 0 0" xyz="0 0 0.05"/>
           <mass value="0.241"/>
           <inertia ixx="0" ixy="0" ixz="0" iyy="0" iyz="0" izz="0"/>
        </inertial>
       <visual>
          <origin rpy="0 0 0" xyz="0 0 0.05"/>
          <geometry>
            <box size="0.1 0.02 0.1" />
                   <!-- <mesh filename="gripper1.stl" scale="1 1 1"/>-->
          </geometry>
           <material name="yellow">
          </material>
        </visual>
        
        <collision  >
          <origin rpy="0 0 0" xyz="0 0  0.05"/>
          <geometry>
            <box size="0.1 0.02 0.1" />
                    <!-- <mesh filename="gripper1.stl" scale="1 1 1"/>-->
          </geometry>
        </collision>
    </link>
    
	<joint name="gripper_upper_arm_gripper1" type="continuous">
		<axis xyz="0 0 1"/>
		<parent link="gripper_upper_arm"/>
		<child link="gripper1"/>
		<origin rpy="0 0 0" xyz="0.03 0.06 0.365"/>
		<limit effort="100" velocity="100"/>
		<joint_properties damping=".0" friction=".0"/>
	</joint>
    
    <link name="gripper2">
      <contact>
          <lateral_friction value="1"/>
      </contact>
        <inertial>
          <origin rpy="1.57 0 -1.57" xyz="0 0 0"/>
           <mass value="0.241"/>
           <inertia ixx="0" ixy="0" ixz="0" iyy="0" iyz="0" izz="0"/>
        </inertial>
       <visual>
          <origin rpy="1.57 0 -1.57" xyz="0 0 0"/>
          <geometry>
                    <mesh filename="gripper2.stl" scale="1.3 1.3 1"/>
          </geometry>
           <material name="yellow">
          </material>
        </visual>
        
        <collision  >
          <origin rpy="1.57 0 -1.57" xyz="0 0 0"/>
          <geometry>
                    <mesh filename="gripper2.stl" scale="1.3 1.3 1"/>
          </geometry>
        </collision>
    </link>
    
	<joint name="gripper1_gripper2" type="continuous">
		<axis xyz="1 0 0"/>
		<parent link="gripper1"/>
		<child link="gripper2"/>
		<origin rpy="0 0 0" xyz="0.05 0.08 0.01"/>
		<limit effort="100" velocity="100"/>
		<joint_properties damping=".0" friction=".0"/>
	</joint>
    
</robot>

