<?xml version="0.0" ?>
<robot name="plane">
    <link name="base_link">
    <inertial>
      <origin rpy="0 1.57 0" xyz="0.26 0 0.25"/>
       <mass value="0.01"/>
       <inertia ixx="0" ixy="0" ixz="0" iyy="0" iyz="0" izz="0"/>
    </inertial>
      <visual>
        <origin rpy="0 1.57 0" xyz="0.26 0 0.25"/>
        <geometry>
          <cylinder length="0.5" radius="0.015"/>
        </geometry>
        <material name="green">
        <color rgba="0 1 0 1"/>
      </material>
      </visual>
      <collision>
      <origin rpy="0 1.57 0" xyz="0.26 0 0.25"/>
          <geometry>
            <cylinder length="0.5" radius="0.015"/>
          </geometry>
      </collision>
    </link>
    
    <link name="bell1">
    <inertial>
      <origin rpy="0 0 0" xyz="0 0 0.25"/>
       <mass value="0.01"/>
       <inertia ixx="0" ixy="0" ixz="0" iyy="0" iyz="0" izz="0"/>
    </inertial>
      <visual>
        <origin rpy="0 0 0" xyz="0 0 0.25"/>
        <geometry>
          <box size="0.02 0.5 0.5"/>
        </geometry>
        <material name="green">
        <color rgba="0 1 0 1"/>
      </material>
      </visual>
      <collision>
      <origin rpy="0 0 0" xyz="0 0 0.25"/>
          <geometry>
            <box size="0.02 0.5 0.5"/>
          </geometry>
      </collision>
      </link>
      
      
       <joint name="bell1_link" type="continuous">
		<axis xyz="1 0 0"/>
		<parent link="bell1"/>
		<child link="base_link"/>
		<origin rpy="0 0 0" xyz="0 0 0"/>
		<limit effort="100" velocity="100"/>
		<joint_properties damping=".0" friction=".0"/>
	</joint>
    
    
    <link name="bell2">
    <inertial>
      <origin rpy="0 0 0" xyz="0 0 0.25"/>
       <mass value="0.01"/>
       <inertia ixx="0" ixy="0" ixz="0" iyy="0" iyz="0" izz="0"/>
    </inertial>
      <visual>
        <origin rpy="0 0 0" xyz="0 0 0.25"/>
        <geometry>
          <box size="0.02 0.5 0.5"/>
        </geometry>
        <material name="green">
        <color rgba="0 1 0 1"/>
      </material>
      </visual>
      <collision>
      <origin rpy="0 0 0" xyz="0 0 0.25"/>
          <geometry>
            <box size="0.02 0.5 0.5"/>
          </geometry>
      </collision>
      </link>
      
      <joint name="bell2_link" type="continuous">
		<axis xyz="1 0 0"/>
		<parent link="base_link"/>
		<child link="bell2"/>
		<origin rpy="0 0 0" xyz="0.52 0 0"/>
		<limit effort="100" velocity="100"/>
		<joint_properties damping=".0" friction=".0"/>
	</joint>
</robot>